<?xml version="1.0" encoding="utf-8"?>
<robot name="piper">

  <link name="base_link">
    <inertial>
      <origin xyz="-0.00473641164191482 2.56829134630247e-05 0.041451518036016" rpy="0 0 0"/>
      <mass value="1.02"/>
      <inertia ixx="0.00267433" ixy="0" ixz="0" iyy="0.00282612" iyz="0" izz="0.00089624"/>
    </inertial>
    <visual>
      <origin xyz="0 0 0.05" rpy="0 0 0"/>
      <geometry>
        <cylinder radius="0.05" length="0.1"/>
      </geometry>
      <material name="light_blue">
        <color rgba="0.792 0.819 0.933 1"/>
      </material>
    </visual>
  </link>

  <joint name="joint1" type="revolute">
    <parent link="base_link"/>
    <child link="link1"/>
    <origin xyz="0 0 0.123" rpy="0 0 0"/>
    <axis xyz="0 0 1"/>
    <limit lower="-2.618" upper="2.168" effort="90.0" velocity="3.14"/>
    <dynamics damping="5.0"/>
  </joint>

  <link name="link1">
    <inertial>
      <origin xyz="0.000121504734057468 0.000104632162460536 -0.00438597309559853" rpy="0 0 0"/>
      <mass value="0.71"/>
      <inertia ixx="0.00048916" ixy="0" ixz="0" iyy="0.00040472" iyz="0" izz="0.00043982"/>
    </inertial>
    <visual>
      <origin xyz="0 0 0.04" rpy="0 0 0"/>
      <geometry>
        <cylinder radius="0.04" length="0.08"/>
      </geometry>
    </visual>
  </link>

  <joint name="joint2" type="revolute">
    <parent link="link1"/>
    <child link="link2"/>
    <origin xyz="0 0 0" rpy="-1.5708 0 -1.5708"/>
    <axis xyz="0 0 1"/>
    <limit lower="0.0" upper="3.14" effort="20.0" velocity="3.14"/>
    <dynamics damping="5.0"/>
  </joint>

  <link name="link2">
    <inertial>
      <origin xyz="0.198666145229743 -0.010926924140076 0.00142121714502687" rpy="0 0 0"/>
      <mass value="1.17"/>
      <inertia ixx="0.00116918" ixy="0" ixz="0" iyy="0.06785384" iyz="0" izz="0.06774489"/>
    </inertial>
    <visual>
      <origin xyz="0 0 0.05" rpy="0 0 0"/>
      <geometry>
        <box size="0.03 0.03 0.1"/>
      </geometry>
    </visual>
  </link>

  <joint name="joint3" type="revolute">
    <parent link="link2"/>
    <child link="link3"/>
    <origin xyz="0.28503 0 0" rpy="0 0 -1.7937"/>
    <axis xyz="0 0 1"/>
    <limit lower="-2.967" upper="0.0" effort="20.0" velocity="3.14"/>
    <dynamics damping="5.0"/>
  </joint>

  <link name="link3">
    <inertial>
      <origin xyz="-0.0202737662122021 -0.133914995944595 -0.000458682652737356" rpy="0 0 0"/>
      <mass value="0.5"/>
      <inertia ixx="0.01361711" ixy="0" ixz="0" iyy="0.00045024" iyz="0" izz="0.01380322"/>
    </inertial>
    <visual>
      <origin xyz="0 0 0.04" rpy="0 0 0"/>
      <geometry>
        <box size="0.025 0.025 0.08"/>
      </geometry>
    </visual>
  </link>

  <joint name="joint4" type="revolute">
    <parent link="link3"/>
    <child link="link4"/>
    <origin xyz="-0.021984 -0.25075 0" rpy="1.5708 0 0"/>
    <axis xyz="0 0 1"/>
    <limit lower="-1.745" upper="1.745" effort="10.0" velocity="3.14"/>
    <dynamics damping="5.0"/>
  </joint>

  <link name="link4">
    <inertial>
      <origin xyz="-9.66635791618542e-05 0.000876064475651083 -0.00496880904640868" rpy="0 0 0"/>
      <mass value="0.38"/>
      <inertia ixx="0.00018501" ixy="0" ixz="0" iyy="0.00018965" iyz="0" izz="0.00015484"/>
    </inertial>
    <visual>
      <origin xyz="0 0 0.015" rpy="0 0 0"/>
      <geometry>
        <cylinder radius="0.02" length="0.03"/>
      </geometry>
    </visual>
  </link>

  <joint name="joint5" type="revolute">
    <parent link="link4"/>
    <child link="link5"/>
    <origin xyz="0 0 0" rpy="-1.5708 0 0"/>
    <axis xyz="0 0 1"/>
    <limit lower="-1.22" upper="1.22" effort="10.0" velocity="3.14"/>
    <dynamics damping="5.0"/>
  </joint>

  <link name="link5">
    <inertial>
      <origin xyz="-4.10554118924211e-05 -0.0566486692356075 -0.0037205791677906" rpy="0 0 0"/>
      <mass value="0.383"/>
      <inertia ixx="0.00166169" ixy="0" ixz="0" iyy="0.0001851" iyz="0" izz="0.00164321"/>
    </inertial>
    <visual>
      <origin xyz="0 0 0.0125" rpy="0 0 0"/>
      <geometry>
        <cylinder radius="0.015" length="0.025"/>
      </geometry>
    </visual>
  </link>

  <joint name="joint6" type="revolute">
    <parent link="link5"/>
    <child link="link6"/>
    <origin xyz="8.8259e-05 -0.091 0" rpy="1.5708 0 0"/>
    <axis xyz="0 0 1"/>
    <limit lower="-2.0944" upper="2.0944" effort="10.0" velocity="3.14"/>
    <dynamics damping="5.0"/>
  </joint>

  <link name="link6">
    <inertial>
      <origin xyz="-8.82590762930069e-05 9.0598378529832e-06 -0.002" rpy="0 0 0"/>
      <mass value="0.007"/>
      <inertia ixx="5.73e-07" ixy="0" ixz="0" iyy="5.73e-07" iyz="0" izz="1.06e-06"/>
    </inertial>
    <visual>
      <origin xyz="0 0 0.01" rpy="0 0 0"/>
      <geometry>
        <cylinder radius="0.01" length="0.02"/>
      </geometry>
      <material name="grey">
        <color rgba="0.898 0.917 0.929 1"/>
      </material>
    </visual>
  </link>

  <link name="end_effector_link"/>
  <joint name="end_effector_joint" type="fixed">
    <parent link="link6"/>
    <child link="end_effector_link"/>
    <origin xyz="0 0 0.02" rpy="0 0 0"/>
  </joint>

</robot>
